Workbook

Sheet Base
A1: Número | B1: Origem | C1: Data Entrada | D1: Problema Identificado | E1: Plano de Ação | F1: Responsável | G1: Prazo | H1: Data Finalização | I1: Status | J1: Dias Atraso | K1: No prazo
A2: 1 | B2: Fórum de Portabilidade | C2: 46029 | D2: PROTOCOLO DE CONFLITOS NÃO GERADOS PARA O BKO PORTABILIDADE (No fechamento de novembro, notamos que aprox. 8% do volume de conflitos do E-commerce entrou em conflito de portabilidade (CPF e Não Habilitado) e não gerou PU automático para tratamento do BKO Portabilidade) | E2: Aberto chamado PDST-2228261 para investigação com equipe do Guilherme Carrasco_x000B_ | F2: Guilherme Carrasco | G2: 46060 | I2: Em andamento | J2: =IF(I2="Concluído","",IF(G2="","",IF(TODAY()>G2,TODAY()-G2,0))) -> 111 | K2: =IF(H2="","Não concluído",IF(H2<=G2,"Concluído no prazo","Concluído fora do prazo")) -> Não concluído
A3: 2 | B3: Fórum de Portabilidade | C3: 46029 | D3: PROTOCOLO DE CONFLITOS NÃO GERADOS PARA O BKO PORTABILIDADE (No fechamento de novembro, notamos que aprox. 8% do volume de conflitos do E-commerce entrou em conflito de portabilidade (CPF e Não Habilitado) e não gerou PU automático para tratamento do BKO Portabilidade) | E3: Ter alarme para sinalizar falha na integração entre SPN e PS8. | F3: Fauzi | G3: 46061 | I3: Em andamento | J3: =IF(I3="Concluído","",IF(G3="","",IF(TODAY()>G3,TODAY()-G3,0))) -> 110 | K3: =IF(H3="","Não concluído",IF(H3<=G3,"Concluído no prazo","Concluído fora do prazo")) -> Não concluído
A4: 3 | B4: Fórum de Portabilidade | C4: 46029 | D4: SAP – PORTABILIDADE INTERNA (Na reunião de portabilidade realizada em 09/12, foi informado por Cícera que há casos de vendas portabilidade interna do canal Televendas sem geração de BP no sistema SAP) | E4: Aberto PDST-2245268 para investigação com time de OGS (TI). No SAP apresenta a mensagem: “Operadora Doadora auto-preenchida deve ser diferente da receptora” | F4: Janaina Cruz | G4: 46062 | I4: Em andamento | J4: =IF(I4="Concluído","",IF(G4="","",IF(TODAY()>G4,TODAY()-G4,0))) -> 109 | K4: =IF(H4="","Não concluído",IF(H4<=G4,"Concluído no prazo","Concluído fora do prazo")) -> Não concluído
A5: 4 | B5: Fórum de Portabilidade | C5: 46043 | D5: Link do site não esta funcionando de maneira correta | E5: Avaliação e correção do link de status de portabilidade no site | F5: Tânia | G5: 46050 | I5: =IF(G5="","",IF(H5<>"","Concluído",IF(TODAY()>G5,"Atrasado","Em andamento"))) -> Atrasado | K5: =IF(H5="","Não concluído",IF(H5<=G5,"Concluído no prazo","Concluído fora do prazo")) -> Não concluído
A6: 5 | B6: Fórum de Portabilidade | C6: 46043 | D6: Reunião Portabilidade | E6: Reforço da comunicação para vendedores e áreas de suporte sobre o fluxo de entrega de chip | F6: Viviane e Natalia | G6: 46050 | H6: 46057 | I6: =IF(G6="","",IF(H6<>"","Concluído",IF(TODAY()>G6,"Atrasado","Em andamento"))) -> Concluído | J6: =IF(I6="Concluído","",IF(G6="","",IF(TODAY()>G6,TODAY()-G6,0))) | K6: =IF(H6="","Não concluído",IF(H6<=G6,"Concluído no prazo","Concluído fora do prazo")) -> Concluído fora do prazo
A7: 6 | B7: Fórum de Portabilidade | C7: 46043 | D7: Apresentação dos indicadores | E7: Acompanhamento dos indicadores de reagendamento e ocorrências aos finais de semana, com retorno em próxima agenda | F7: Cícera e Galvão | G7: 46050 | H7: 46050 | I7: =IF(G7="","",IF(H7<>"","Concluído",IF(TODAY()>G7,"Atrasado","Em andamento"))) -> Concluído | J7: =IF(I7="Concluído","",IF(G7="","",IF(TODAY()>G7,TODAY()-G7,0))) | K7: =IF(H7="","Não concluído",IF(H7<=G7,"Concluído no prazo","Concluído fora do prazo")) -> Concluído no prazo
A8: 7 | B8: Fórum de Portabilidade | C8: 46050 | D8: Instabilidades de DDD 6XX / Chip | E8: Acompanhar chamado casos DDD 6XX acompanhar os testes com BKO técnico | F8: Diego | G8: 46057 | H8: 46057 | I8: =IF(G8="","",IF(H8<>"","Concluído",IF(TODAY()>G8,"Atrasado","Em andamento"))) -> Concluído | J8: =IF(I8="Concluído","",IF(G8="","",IF(TODAY()>G8,TODAY()-G8,0))) | K8: =IF(H8="","Não concluído",IF(H8<=G8,"Concluído no prazo","Concluído fora do prazo")) -> Concluído no prazo
A9: 8 | B9: Fórum de Portabilidade | C9: 46050 | D9: DDP OS160257 | E9: TI implantar a correção do sincronismo SPN x BR - Aline verificar prazo com TI | F9: Aline | G9: 46057 | H9: 46088 | I9: =IF(G9="","",IF(H9<>"","Concluído",IF(TODAY()>G9,"Atrasado","Em andamento"))) -> Concluído | J9: =IF(I9="Concluído","",IF(G9="","",IF(TODAY()>G9,TODAY()-G9,0))) | K9: =IF(H9="","Não concluído",IF(H9<=G9,"Concluído no prazo","Concluído fora do prazo")) -> Concluído fora do prazo
A10: 9 | B10: Fórum de Portabilidade | C10: 46050 | D10: Bilhete cancelado | E10: Ajustar lógica de envio de SMS em bilhetes cancelados - Aline verificar com ABR | F10: Aline | G10: 46057 | H10: 46063 | I10: =IF(G10="","",IF(H10<>"","Concluído",IF(TODAY()>G10,"Atrasado","Em andamento"))) -> Concluído | J10: =IF(I10="Concluído","",IF(G10="","",IF(TODAY()>G10,TODAY()-G10,0))) | K10: =IF(H10="","Não concluído",IF(H10<=G10,"Concluído no prazo","Concluído fora do prazo")) -> Concluído fora do prazo
A11: 10 | B11: Fórum de Portabilidade | C11: 46050 | D11: Ativação CHIP | E11: Validar qual é o processo oficial quando o cliente procura a loja solicitando ajuda para ativar o chip, garantindo padronização no atendimento. | F11: - Borges e Vivi Becker | G11: 46057 | H11: 46057 | I11: =IF(G11="","",IF(H11<>"","Concluído",IF(TODAY()>G11,"Atrasado","Em andamento"))) -> Concluído | J11: =IF(I11="Concluído","",IF(G11="","",IF(TODAY()>G11,TODAY()-G11,0))) | K11: =IF(H11="","Não concluído",IF(H11<=G11,"Concluído no prazo","Concluído fora do prazo")) -> Concluído no prazo
A12: 11 | B12: Fórum de Portabilidade | C12: 46051 | D12: Ativação CHIP | E12: Garantir que as informações estejam claras no SIM Card e no Kit Welcome, evitando dúvidas durante o atendimento. | F12: Marketing | G12: 46057 | H12: 46057 | I12: =IF(G12="","",IF(H12<>"","Concluído",IF(TODAY()>G12,"Atrasado","Em andamento"))) -> Concluído | J12: =IF(I12="Concluído","",IF(G12="","",IF(TODAY()>G12,TODAY()-G12,0))) | K12: =IF(H12="","Não concluído",IF(H12<=G12,"Concluído no prazo","Concluído fora do prazo")) -> Concluído no prazo
A13: 12 | B13: Fórum de Portabilidade | C13: 46051 | D13: Ativação CHIP | E13: Confirmar se o conteúdo orientativo está disponível para a equipe de atendimento, e identificar onde esse material está localizado para facilitar acesso e consulta. | F13: - Borges e Vivi Becker | G13: 46058 | H13: 46058 | I13: =IF(G13="","",IF(H13<>"","Concluído",IF(TODAY()>G13,"Atrasado","Em andamento"))) -> Concluído | J13: =IF(I13="Concluído","",IF(G13="","",IF(TODAY()>G13,TODAY()-G13,0))) | K13: =IF(H13="","Não concluído",IF(H13<=G13,"Concluído no prazo","Concluído fora do prazo")) -> Concluído no prazo
A14: 13 | B14: Fórum de Portabilidade | C14: 46057 | D14: Instabilidades de DDD 6XX / Chip | E14: Realizar Rastreamento do caso DDD6X, para identificar causa raiz e realizar abrangência para garantir que não tenha mais lote não conforme | F14: Hebert | G14: 46064 | H14: 46064 | I14: =IF(G14="","",IF(H14<>"","Concluído",IF(TODAY()>G14,"Atrasado","Em andamento"))) -> Concluído | J14: =IF(I14="Concluído","",IF(G14="","",IF(TODAY()>G14,TODAY()-G14,0))) | K14: =IF(H14="","Não concluído",IF(H14<=G14,"Concluído no prazo","Concluído fora do prazo")) -> Concluído no prazo
A15: 14 | B15: Fórum de Portabilidade | C15: 46057 | D15: Instabilidades de DDD 6XX / Chip | E15: Executar plano de substituição conforme fluxo definido e acompanha impacto do lote DDD6X | F15: Diego | G15: 46064 | H15: 46064 | I15: =IF(G15="","",IF(H15<>"","Concluído",IF(TODAY()>G15,"Atrasado","Em andamento"))) -> Concluído | J15: =IF(I15="Concluído","",IF(G15="","",IF(TODAY()>G15,TODAY()-G15,0))) | K15: =IF(H15="","Não concluído",IF(H15<=G15,"Concluído no prazo","Concluído fora do prazo")) -> Concluído no prazo
A16: 15 | B16: Fórum de Portabilidade | C16: 46064 | D16: DDP DDPs 160749 e 160750 Falha Atualização do Status do Bilhete | E16: Validar geração de protocolo pós-tratativa OGS e confirmar regularização do fluxo BKO | F16: Rogerio Galvão | G16: 46073 | H16: 46088 | I16: =IF(G16="","",IF(H16<>"","Concluído",IF(TODAY()>G16,"Atrasado","Em andamento"))) -> Concluído | J16: =IF(I16="Concluído","",IF(G16="","",IF(TODAY()>G16,TODAY()-G16,0))) | K16: =IF(H16="","Não concluído",IF(H16<=G16,"Concluído no prazo","Concluído fora do prazo")) -> Concluído fora do prazo
A17: 16 | B17: Fórum de Portabilidade | C17: 46064 | D17: Reunião Portabilidade | E17: Verificar com André Sbarai a revisão do fluxo de atendimento | F17: Diego | G17: 46073 | H17: 46073 | I17: =IF(G17="","",IF(H17<>"","Concluído",IF(TODAY()>G17,"Atrasado","Em andamento"))) -> Concluído | J17: =IF(I17="Concluído","",IF(G17="","",IF(TODAY()>G17,TODAY()-G17,0))) | K17: =IF(H17="","Não concluído",IF(H17<=G17,"Concluído no prazo","Concluído fora do prazo")) -> Concluído no prazo
... A32: 31 | B32: Fórum de Portabilidade | C32: 46099 | D32: Aumento manifestações da Anatel | E32: Agendar reunião específica para processo de portabilidade sem bilhete | F32: Diego | G32: 46105 | H32: 46105 | I32: =IF(G32="","",IF(H32<>"","Concluído",IF(TODAY()>G32,"Atrasado","Em andamento"))) -> Concluído | J32: =IF(I32="Concluído","",IF(G32="","",IF(TODAY()>G32,TODAY()-G32,0))) | K32: =IF(H32="","Não concluído",IF(H32<=G32,"Concluído no prazo","Concluído fora do prazo")) -> Concluído no prazo
A33: 32 | B33: Fórum de Portabilidade | C33: 46099 | D33: PORTABILIDADE INTERNA- Demanda skill preferencial | E33: Abertura de demanda no Hike para maling de direcionamento de Portabilidade Interna para o Skill preferencial. | F33: Diego | G33: 46105 | I33: Em andamento | J33: =IF(I33="Concluído","",IF(G33="","",IF(TODAY()>G33,TODAY()-G33,0))) -> 66 | K33: =IF(H33="","Não concluído",IF(H33<=G33,"Concluído no prazo","Concluído fora do prazo")) -> Não concluído
A34: 33 | B34: Fórum de Portabilidade | C34: 46099 | D34: Implantação da melhoria nas mensagens do sistema ativação simplificada eliminando mensagens genéricas. | E34: Enviar comunicado para os canais de vendas. | F34: Viviane | G34: 46105 | H34: 46111 | I34: =IF(G34="","",IF(H34<>"","Concluído",IF(TODAY()>G34,"Atrasado","Em andamento"))) -> Concluído | J34: =IF(I34="Concluído","",IF(G34="","",IF(TODAY()>G34,TODAY()-G34,0))) | K34: =IF(H34="","Não concluído",IF(H34<=G34,"Concluído no prazo","Concluído fora do prazo")) -> Concluído fora do prazo
A35: 34 | B35: Fórum de Portabilidade | C35: 45741 | D35: PA Qualificadora | E35: Envio da PA Qualificcadora | F35: Diego | G35: 46108 | H35: 46108 | I35: =IF(G35="","",IF(H35<>"","Concluído",IF(TODAY()>G35,"Atrasado","Em andamento"))) -> Concluído | J35: =IF(I35="Concluído","",IF(G35="","",IF(TODAY()>G35,TODAY()-G35,0))) | K35: =IF(H35="","Não concluído",IF(H35<=G35,"Concluído no prazo","Concluído fora do prazo")) -> Concluído no prazo
A36: 35 | B36: Fórum de Portabilidade | C36: 45741 | D36: Processos nas Lojas Clientes relataram que vendedores estão retendo o chip, o que impede o aceite do SMS de portabilidade | E36: Publicar comunicado de reforço por 3 semanas card em 24/03 (nº 1323505931) e haverá reforço operacional junto a vendedores e gerentes. | F36: Natalia | G36: 46113 | H36: 46127 | I36: =IF(G36="","",IF(H36<>"","Concluído",IF(TODAY()>G36,"Atrasado","Em andamento"))) -> Concluído | J36: =IF(I36="Concluído","",IF(G36="","",IF(TODAY()>G36,TODAY()-G36,0))) | K36: =IF(H36="","Não concluído",IF(H36<=G36,"Concluído no prazo","Concluído fora do prazo")) -> Concluído fora do prazo
A37: 36 | B37: Fórum de Portabilidade | C37: 45741 | D37: Sistema Ativação Simplificada | E37: Envio do comunicado sobre Mensagens de Portabilidade no Sistema Ativação Simplificada para todos os canais. | F37: Vivi | G37: 46105 | H37: 46105 | I37: =IF(G37="","",IF(H37<>"","Concluído",IF(TODAY()>G37,"Atrasado","Em andamento"))) -> Concluído | J37: =IF(I37="Concluído","",IF(G37="","",IF(TODAY()>G37,TODAY()-G37,0))) | K37: =IF(H37="","Não concluído",IF(H37<=G37,"Concluído no prazo","Concluído fora do prazo")) -> Concluído no prazo
A38: 37 | B38: Fórum de Portabilidade | C38: 45741 | D38: Portabilidade e Sobreposição Solicitação de portabilidade de Pré Pago para sobrepor uma linha que está pré ativa como Controle ou Pós-pago | E38: Identificar possíveis causas operacionais ou sistêmicas | F38: Borges | G38: 46115 | H38: 46120 | I38: =IF(G38="","",IF(H38<>"","Concluído",IF(TODAY()>G38,"Atrasado","Em andamento"))) -> Concluído | J38: =IF(I38="Concluído","",IF(G38="","",IF(TODAY()>G38,TODAY()-G38,0))) | K38: =IF(H38="","Não concluído",IF(H38<=G38,"Concluído no prazo","Concluído fora do prazo")) -> Concluído fora do prazo
A39: 38 | B39: Fórum de Portabilidade | C39: 45741 | D39: Aumento de conflitos de CPF divergente sem tratamento em loja, principalmente em clientes Combo Multi | E39: 1. Verificar se há alguma falha sistêmica | F39: Borges | G39: 46115 | H39: 46127 | I39: =IF(G39="","",IF(H39<>"","Concluído",IF(TODAY()>G39,"Atrasado","Em andamento"))) -> Concluído | J39: =IF(I39="Concluído","",IF(G39="","",IF(TODAY()>G39,TODAY()-G39,0))) | K39: =IF(H39="","Não concluído",IF(H39<=G39,"Concluído no prazo","Concluído fora do prazo")) -> Concluído fora do prazo
A40: 39 | B40: Fórum de Portabilidade | C40: 45741 | D40: Aumento de conflitos de CPF divergente sem tratamento em loja, principalmente em clientes Combo Multi | E40: 2. Caso não seja verificado erro sistêmico, será realizado reforço pontual, comunicado e, se necessário, visita às lojas. | F40: Natalia | G40: 46115 | H40: 46127 | I40: =IF(G40="","",IF(H40<>"","Concluído",IF(TODAY()>G40,"Atrasado","Em andamento"))) -> Concluído | J40: =IF(I40="Concluído","",IF(G40="","",IF(TODAY()>G40,TODAY()-G40,0))) | K40: =IF(H40="","Não concluído",IF(H40<=G40,"Concluído no prazo","Concluído fora do prazo")) -> Concluído fora do prazo
A41: 40 | B41: Fórum de Portabilidade | C41: 46127 | D41: CANCELAMENTO NÃO REALIZADO (Conforme análise de verbatins dos clientes, existem muitas reclamações de cancelamento de portabilidade não realizada) | E41: Ampliar análise de casos de cancelamento não realizado para maior assertividade. | F41: Diego | G41: 46133 | I41: Em andamento | J41: =IF(I41="Concluído","",IF(G41="","",IF(TODAY()>G41,TODAY()-G41,0))) -> 38 | K41: =IF(H41="","Não concluído",IF(H41<=G41,"Concluído no prazo","Concluído fora do prazo")) -> Não concluído
A42: 41 | B42: Fórum de Portabilidade | C42: 46127 | D42: Token Anatel | E42: Selecionar e documentar casos de Token ANATEL (Ativação Simplificada) para abertura de chamado. | F42: Cristiane | G42: 46133 | H42: 46147 | I42: =IF(G42="","",IF(H42<>"","Concluído",IF(TODAY()>G42,"Atrasado","Em andamento"))) -> Concluído | J42: =IF(I42="Concluído","",IF(G42="","",IF(TODAY()>G42,TODAY()-G42,0))) | K42: =IF(H42="","Não concluído",IF(H42<=G42,"Concluído no prazo","Concluído fora do prazo")) -> Concluído fora do prazo
A43: 42 | B43: Fórum de Portabilidade | C43: 46134 | D43: Lentidão SPN (Token e Bilhete) Atraso em relação aos bilhetes e token da ABR | E43: Continuar monitorando possíveis ocorrências de lentidão no SPN, especialmente em janelas de pico, com foco em bilhete, reagendamento e disparo de SMS/token. | F43: Galvão, Roldão, Diego e Cícera | G43: 46142 | H43: 46147 | I43: =IF(G43="","",IF(H43<>"","Concluído",IF(TODAY()>G43,"Atrasado","Em andamento"))) -> Concluído | J43: =IF(I43="Concluído","",IF(G43="","",IF(TODAY()>G43,TODAY()-G43,0))) | K43: =IF(H43="","Não concluído",IF(H43<=G43,"Concluído no prazo","Concluído fora do prazo")) -> Concluído fora do prazo
A44: 43 | B44: Fórum de Portabilidade | C44: 46134 | D44: Chamado ABR – SPN / Token Atraso em relação aos bilhetes e token da ABR | E44: Acompanhar o chamado junto à ABR e reforçar a cobrança para identificação da causa raiz, visando evitar novos impactos operacionais e comerciais | F44: Aline | G44: 46142 | H44: 46147 | I44: =IF(G44="","",IF(H44<>"","Concluído",IF(TODAY()>G44,"Atrasado","Em andamento"))) -> Concluído | J44: =IF(I44="Concluído","",IF(G44="","",IF(TODAY()>G44,TODAY()-G44,0))) | K44: =IF(H44="","Não concluído",IF(H44<=G44,"Concluído no prazo","Concluído fora do prazo")) -> Concluído fora do prazo
A45: 44 | B45: Fórum de Portabilidade | C45: 46134 | D45: Flex – Portabilidade Não Realizada Foi identificado que o sistema não estava enviando o código para a logística, fazendo com que o cliente precisasse acessar o aplicativo Flex e solicitar manualmente o código | E45: Avaliar se a falha no envio do código para logística, decorrente da migração do SAP, está impactando o aumento das reclamações de Portabilidade Não Realizada no Flex | F45: Ieda | G45: 46142 | H45: 46155 | I45: =IF(G45="","",IF(H45<>"","Concluído",IF(TODAY()>G45,"Atrasado","Em andamento"))) -> Concluído | J45: =IF(I45="Concluído","",IF(G45="","",IF(TODAY()>G45,TODAY()-G45,0))) | K45: =IF(H45="","Não concluído",IF(H45<=G45,"Concluído no prazo","Concluído fora do prazo")) -> Concluído fora do prazo
A46: 45 | B46: Fórum de Portabilidade | C46: 46141 | D46: Foram discutidos casos de clientes em processo de portabilidade que não receberam o chip e não possuem número provisório. | E46: Realizar reunião de alinhamento sobre casos MVNO sem chip e definição de devolução/estorno. | F46: Tania | G46: 46148 | I46: =IF(G46="","",IF(H46<>"","Concluído",IF(TODAY()>G46,"Atrasado","Em andamento"))) -> Atrasado | J46: =IF(I46="Concluído","",IF(G46="","",IF(TODAY()>G46,TODAY()-G46,0))) -> 23 | K46: =IF(H46="","Não concluído",IF(H46<=G46,"Concluído no prazo","Concluído fora do prazo")) -> Não concluído
A47: 46 | B47: Fórum de Portabilidade | C47: 46141 | D47: A ABR foi acionada no final de semana devido a instabilidades, durante uma manutenção, foram identificados alguns problemas e realizados testes conjuntos | E47: Acionar TI para cobrança de prazo e tratamento da lentidão interna. | F47: Aline | G47: 46148 | H47: 46148 | I47: =IF(G47="","",IF(H47<>"","Concluído",IF(TODAY()>G47,"Atrasado","Em andamento"))) -> Concluído | J47: =IF(I47="Concluído","",IF(G47="","",IF(TODAY()>G47,TODAY()-G47,0))) | K47: =IF(H47="","Não concluído",IF(H47<=G47,"Concluído no prazo","Concluído fora do prazo")) -> Concluído no prazo
A48: 47 | B48: Fórum de Portabilidade | C48: 46141 | D48: Foi discutido sobre os planos de ações em andamento relacionados ao cliente em loja própria sendo portado como pré-pago, sobreposição do número provisório e também sobre conflito de CPF divergente | E48: Definir e comunicar data do workshop em lojas. | F48: Borges | G48: 46148 | I48: =IF(G48="","",IF(H48<>"","Concluído",IF(TODAY()>G48,"Atrasado","Em andamento"))) -> Atrasado | J48: =IF(I48="Concluído","",IF(G48="","",IF(TODAY()>G48,TODAY()-G48,0))) -> 23 | K48: =IF(H48="","Não concluído",IF(H48<=G48,"Concluído no prazo","Concluído fora do prazo")) -> Não concluído
A49: 48 | B49: Fórum de Portabilidade | C49: 46148 | D49: Aumento significativo no volume de protocolo de SMS sem resposta, com crescimento expressivo no dia 24/04. | E49: Analisar aumento do volume de protocolos de SMS sem resposta, considerando campanhas de SMS e WhatsApp, para identificação de possível falha sistêmica | F49: Galvão | G49: 46155 | H49: 46155 | I49: =IF(G49="","",IF(H49<>"","Concluído",IF(TODAY()>G49,"Atrasado","Em andamento"))) -> Concluído | J49: =IF(I49="Concluído","",IF(G49="","",IF(TODAY()>G49,TODAY()-G49,0))) | K49: =IF(H49="","Não concluído",IF(H49<=G49,"Concluído no prazo","Concluído fora do prazo")) -> Concluído no prazo
A50: 49 | B50: Fórum de Portabilidade | C50: 46148 | D50: Indicadores | E50: Apresentar conceitualmente o que caracteriza portabilidade indevida / não solicitada. | F50: Ieda | G50: 46155 | H50: 46155 | I50: =IF(G50="","",IF(H50<>"","Concluído",IF(TODAY()>G50,"Atrasado","Em andamento"))) -> Concluído | J50: =IF(I50="Concluído","",IF(G50="","",IF(TODAY()>G50,TODAY()-G50,0))) | K50: =IF(H50="","Não concluído",IF(H50<=G50,"Concluído no prazo","Concluído fora do prazo")) -> Concluído no prazo
A51: 50 | B51: Fórum de Portabilidade | C51: 46148 | D51: Portabilidade ocorre sem troca do número provisório para portado, deixando o cliente sem comunicação até tratamento manual | E51: Realizar contato ativo com clientes para confirmação de posse do chip nos casos sem habilitação | F51: Galvão | G51: 46155 | I51: =IF(G51="","",IF(H51<>"","Concluído",IF(TODAY()>G51,"Atrasado","Em andamento"))) -> Atrasado
A52: 51 | B52: Fórum de Portabilidade | C52: 46148 | D52: Portabilidade ocorre sem troca do número provisório para portado, deixando o cliente sem comunicação até tratamento manual | E52: · Alinhar com Raissa o fluxo de tratamento dos casos relacionados ao produto Claro Flex. | F52: Galvão | G52: 46155 | I52: =IF(G52="","",IF(H52<>"","Concluído",IF(TODAY()>G52,"Atrasado","Em andamento"))) -> Atrasado
A53: 52 | B53: Fórum de Portabilidade | C53: 46155 | D53: Foi identificado que o bilhete de portabilidade está chegando zerado no SAP, embora seja corretamente gerado no SPN. | E53: Correção sistêmica para garantir envio correto do SPN para o SAP | F53: TI | G53: 46162 | I53: =IF(G53="","",IF(H53<>"","Concluído",IF(TODAY()>G53,"Atrasado","Em andamento"))) -> Atrasado
A54: 53 | B54: Fórum de Portabilidade | C54: 46155 | D54: Aumento do número de Não Habilitados, com dificuldade do BKOffice em identificar causa raiz. Também há acúmulo de ordens sem entrega, impactando o fluxo. Os reagendamentos estão sendo feitos manualmente ( CARD ABERTO). | E54: Acompanhar indicador de Não Habilitado | F54: Galvão | G54: 46162 | I54: =IF(G54="","",IF(H54<>"","Concluído",IF(TODAY()>G54,"Atrasado","Em andamento"))) -> Atrasado
...

Sheet 📊 Dashboard
B2: PORTABILIDADE PORTIN | Dashboard Executivo
B4: =COUNTA(Base!I2:I60) -> 55 | C4: =COUNTIF(Base!I2:I60,"Concluído") -> 41 | D4: =COUNTIF(Base!I2:I60,"Atrasado") -> 9 | E4: =COUNTIF(Base!I2:I60,"Em Andamento") -> 5 | F4: =IFERROR(TEXT(COUNTIF(Base!I2:I60,"Concluído")/COUNTA(Base!I2:I60),"0.0%"),"-") -> 75%
B5: TOTAL DE AÇÕES | C5: ✅ CONCLUÍDAS | D5: ⚠ ATRASADAS | E5: 🔄 EM ANDAMENTO | F5: 📈 TAXA CONCLUSÃO
B7: STATUS — CONTAGEM POR SITUAÇÃO
B8: Status | C8: Qtd | D8: % do Total
B9: Concluído | C9: =COUNTIF(Base!I2:I60,"Concluído") -> 41 | D9: =IFERROR(COUNTIF(Base!I2:I60,"Concluído")/COUNTA(Base!I2:I60),0) -> 0.74545455
B10: Atrasado | C10: =COUNTIF(Base!I2:I60,"Atrasado") -> 9 | D10: =IFERROR(COUNTIF(Base!I2:I60,"Atrasado")/COUNTA(Base!I2:I60),0) -> 0.16363636
B11: Em Andamento | C11: =COUNTIF(Base!I2:I60,"Em Andamento") -> 5 | D11: =IFERROR(COUNTIF(Base!I2:I48,"Em Andamento")/COUNTA(Base!I2:I60),0) -> 0.090909091
B12: TOTAL | C12: =COUNTA(Base!I2:I60) -> 55 | D12: =100% -> 1
B14: TOP AÇÕES MAIS ATRASADAS
B15: Problema (resumido) | C15: Responsável | D15: Prazo | E15: Dias Atraso
B16: =IFERROR(LEFT(INDEX(Base!D2:D48,MATCH(LARGE(Base!J2:J60,1),Base!J2:J60,0)),70),"-") -> PROTOCOLO DE CONFLITOS NÃO GERADOS PARA O BKO PORTABILIDADE (No fecham | C16: =IFERROR(INDEX(Base!F2:F60,MATCH(LARGE(Base!J2:J60,1),Base!J2:J60,0)),"-") -> Guilherme Carrasco | D16: =IFERROR(INDEX(Base!G2:G60,MATCH(LARGE(Base!J2:J60,1),Base!J2:J60,0)),"-") -> 46060 | E16: =IFERROR(LARGE(Base!J2:J48,1),"") -> 111
B17: =IFERROR(LEFT(INDEX(Base!D3:D49,MATCH(LARGE(Base!J3:J61,1),Base!J3:J61,0)),70),"-") -> PROTOCOLO DE CONFLITOS NÃO GERADOS PARA O BKO PORTABILIDADE (No fecham | C17: =IFERROR(INDEX(Base!F3:F61,MATCH(LARGE(Base!J3:J61,1),Base!J3:J61,0)),"-") -> Fauzi | D17: =IFERROR(INDEX(Base!G2:G60,MATCH(LARGE(Base!J2:J48,2),Base!J2:J48,0)),"-") -> 46061 | E17: =IFERROR(LARGE(Base!J2:J48,2),"") -> 110
B18: =IFERROR(LEFT(INDEX(Base!D4:D50,MATCH(LARGE(Base!J4:J62,1),Base!J4:J62,0)),70),"-") -> SAP – PORTABILIDADE INTERNA (Na reunião de portabilidade realizada em | C18: =IFERROR(INDEX(Base!F4:F62,MATCH(LARGE(Base!J4:J62,1),Base!J4:J62,0)),"-") -> Janaina Cruz | D18: =IFERROR(INDEX(Base!G2:G48,MATCH(LARGE(Base!J2:J60,3),Base!J2:J48,0)),"-") -> 46062 | E18: =IFERROR(LARGE(Base!J2:J48,3),"") -> 109
B19: =IFERROR(LEFT(INDEX(Base!D5:D51,MATCH(LARGE(Base!J5:J63,1),Base!J5:J63,0)),70),"-") -> PORTABILIDADE INTERNA- Demanda skill preferencial | C19: =IFERROR(INDEX(Base!F5:F63,MATCH(LARGE(Base!J5:J63,1),Base!J5:J63,0)),"-") -> Diego | D19: =IFERROR(INDEX(Base!G2:G48,MATCH(LARGE(Base!J2:J48,4),Base!J2:J60,0)),"-") -> 46105 | E19: =IFERROR(LARGE(Base!J2:J48,4),"") -> 66
B20: =IFERROR(LEFT(INDEX(Base!D6:D52,MATCH(LARGE(Base!J6:J64,1),Base!J6:J64,0)),70),"-") -> PORTABILIDADE INTERNA- Demanda skill preferencial | C20: =IFERROR(INDEX(Base!F6:F64,MATCH(LARGE(Base!J6:J64,1),Base!J6:J64,0)),"-") -> Diego | D20: =IFERROR(INDEX(Base!G2:G48,MATCH(LARGE(Base!J2:J48,5),Base!J2:J48,0)),"-") -> 46133 | E20: =IFERROR(LARGE(Base!J2:J48,5),"") -> 38
B21: =IFERROR(LEFT(INDEX(Base!D7:D53,MATCH(LARGE(Base!J7:J65,1),Base!J7:J65,0)),70),"-") -> PORTABILIDADE INTERNA- Demanda skill preferencial | C21: =IFERROR(INDEX(Base!F7:F65,MATCH(LARGE(Base!J7:J65,1),Base!J7:J65,0)),"-") -> Diego | D21: =IFERROR(INDEX(Base!G2:G48,MATCH(LARGE(Base!J2:J48,6),Base!J2:J48,0)),"-") -> 46148 | E21: =IFERROR(LARGE(Base!J2:J48,6),"") -> 23

Sheet 📋 Resumo Executivo
B2: PORTIN — Resumo Executivo do Plano de Ação
B3: ="Atualizado em: "&TEXT(TODAY(),"DD/MM/YYYY")&" | Total: "&COUNTA(Base!I2:I48)&" ações | Concluídas: "&COUNTIF(Base!I2:I48,"Concluído")&" | Atrasadas: "&COUNTIF(Base!I2:I48,"Atrasado")&" | Em andamento: "&COUNTIF(Base!I2:I48,"Em Andamento") -> Atualizado em: 29/05/YYYY | Total: 47 ações | Concluídas: 39 | Atrasadas: 3 | Em andamento: 5
B4: SITUAÇÃO / PROBLEMA | C4: PLANO DE AÇÃO | D4: RESPONSÁVEL | E4: PRAZO | F4: STATUS
B5: =IFERROR(LEFT(Base!D2,85),"") -> PROTOCOLO DE CONFLITOS NÃO GERADOS PARA O BKO PORTABILIDADE (No fechamento de novembr | C5: =IFERROR(LEFT(Base!E2,130),"") -> Aberto chamado PDST-2228261 para investigação com equipe do Guilherme Carrasco_x000B_ | D5: =IFERROR(Base!F2,"") -> Guilherme Carrasco | E5: =IFERROR(Base!G2,"-") -> 46060 | F5: =IFERROR(IF(Base!J2>0,Base!I2&" ("&Base!J2&"d atraso)",Base!I2),"") -> Em andamento (111d atraso)
B6: =IFERROR(LEFT(Base!D3,85),"") -> PROTOCOLO DE CONFLITOS NÃO GERADOS PARA O BKO PORTABILIDADE (No fechamento de novembr | C6: =IFERROR(LEFT(Base!E3,130),"") -> Ter alarme para sinalizar falha na integração entre SPN e PS8. | D6: =IFERROR(Base!F3,"") -> Fauzi | E6: =IFERROR(Base!G3,"-") -> 46061 | F6: =IFERROR(IF(Base!J3>0,Base!I3&" ("&Base!J3&"d atraso)",Base!I3),"") -> Em andamento (110d atraso)
B7: =IFERROR(LEFT(Base!D4,85),"") -> SAP – PORTABILIDADE INTERNA (Na reunião de portabilidade realizada em 09/12, foi info | C7: =IFERROR(LEFT(Base!E4,130),"") -> Aberto PDST-2245268 para investigação com time de OGS (TI). No SAP apresenta a mensagem: “Operadora Doadora auto-preenchida deve s | D7: =IFERROR(Base!F4,"") -> Janaina Cruz | E7: =IFERROR(Base!G4,"-") -> 46062 | F7: =IFERROR(IF(Base!J4>0,Base!I4&" ("&Base!J4&"d atraso)",Base!I4),"") -> Em andamento (109d atraso)
B8: =IFERROR(LEFT(Base!D5,85),"") -> Link do site não esta funcionando de maneira correta | C8: =IFERROR(LEFT(Base!E5,130),"") -> Avaliação e correção do link de status de portabilidade no site | D8: =IFERROR(Base!F5,"") -> Tânia | E8: =IFERROR(Base!G5,"-") -> 46050 | F8: =IFERROR(IF(Base!J5>0,Base!I5&" ("&Base!J5&"d atraso)",Base!I5),"") -> Atrasado
B9: =IFERROR(LEFT(Base!D6,85),"") -> Reunião Portabilidade | C9: =IFERROR(LEFT(Base!E6,130),"") -> Reforço da comunicação para vendedores e áreas de suporte sobre o fluxo de entrega de chip | D9: =IFERROR(Base!F6,"") -> Viviane e Natalia | E9: =IFERROR(Base!G6,"-") -> 46050 | F9: =IFERROR(IF(Base!J6>0,Base!I6&" ("&Base!J6&"d atraso)",Base!I6),"") -> Concluído (d atraso)
B10: =IFERROR(LEFT(Base!D7,85),"") -> Apresentação dos indicadores | C10: =IFERROR(LEFT(Base!E7,130),"") -> Acompanhamento dos indicadores de reagendamento e ocorrências aos finais de semana, com retorno em próxima agenda | D10: =IFERROR(Base!F7,"") -> Cícera e Galvão | E10: =IFERROR(Base!G7,"-") -> 46050 | F10: =IFERROR(IF(Base!J7>0,Base!I7&" ("&Base!J7&"d atraso)",Base!I7),"") -> Concluído (d atraso)
B11: =IFERROR(LEFT(Base!D8,85),"") -> Instabilidades de DDD 6XX / Chip | C11: =IFERROR(LEFT(Base!E8,130),"") -> Acompanhar chamado casos DDD 6XX acompanhar os testes com BKO técnico | D11: =IFERROR(Base!F8,"") -> Diego | E11: =IFERROR(Base!G8,"-") -> 46057 | F11: =IFERROR(IF(Base!J8>0,Base!I8&" ("&Base!J8&"d atraso)",Base!I8),"") -> Concluído (d atraso)
B12: =IFERROR(LEFT(Base!D9,85),"") -> DDP OS160257 | C12: =IFERROR(LEFT(Base!E9,130),"") -> TI implantar a correção do sincronismo SPN x BR - Aline verificar prazo com TI | D12: =IFERROR(Base!F9,"") -> Aline | E12: =IFERROR(Base!G9,"-") -> 46057 | F12: =IFERROR(IF(Base!J9>0,Base!I9&" ("&Base!J9&"d atraso)",Base!I9),"") -> Concluído (d atraso)
B13: =IFERROR(LEFT(Base!D10,85),"") -> Bilhete cancelado | C13: =IFERROR(LEFT(Base!E10,130),"") -> Ajustar lógica de envio de SMS em bilhetes cancelados - Aline verificar com ABR | D13: =IFERROR(Base!F10,"") -> Aline | E13: =IFERROR(Base!G10,"-") -> 46057 | F13: =IFERROR(IF(Base!J10>0,Base!I10&" ("&Base!J10&"d atraso)",Base!I10),"") -> Concluído (d atraso)
B14: =IFERROR(LEFT(Base!D11,85),"") -> Ativação CHIP | C14: =IFERROR(LEFT(Base!E11,130),"") -> Validar qual é o processo oficial quando o cliente procura a loja solicitando ajuda para ativar o chip, garantindo padronização no | D14: =IFERROR(Base!F11,"") -> - Borges e Vivi Becker | E14: =IFERROR(Base!G11,"-") -> 46057 | F14: =IFERROR(IF(Base!J11>0,Base!I11&" ("&Base!J11&"d atraso)",Base!I11),"") -> Concluído (d atraso)
B15: =IFERROR(LEFT(Base!D12,85),"") -> Ativação CHIP | C15: =IFERROR(LEFT(Base!E12,130),"") -> Garantir que as informações estejam claras no SIM Card e no Kit Welcome, evitando dúvidas durante o atendimento. | D15: =IFERROR(Base!F12,"") -> Marketing | E15: =IFERROR(Base!G12,"-") -> 46057 | F15: =IFERROR(IF(Base!J12>0,Base!I12&" ("&Base!J12&"d atraso)",Base!I12),"") -> Concluído (d atraso)
B16: =IFERROR(LEFT(Base!D13,85),"") -> Ativação CHIP | C16: =IFERROR(LEFT(Base!E13,130),"") -> Confirmar se o conteúdo orientativo está disponível para a equipe de atendimento, e identificar onde esse material está localizado | D16: =IFERROR(Base!F13,"") -> - Borges e Vivi Becker | E16: =IFERROR(Base!G13,"-") -> 46058 | F16: =IFERROR(IF(Base!J13>0,Base!I13&" ("&Base!J13&"d atraso)",Base!I13),"") -> Concluído (d atraso)
... B43: =IFERROR(LEFT(Base!D40,85),"") -> Aumento de conflitos de CPF divergente sem tratamento em loja, principalmente em clie | C43: =IFERROR(LEFT(Base!E40,130),"") -> 2. Caso não seja verificado erro sistêmico, será realizado reforço pontual, comunicado e, se necessário, visita às lojas. | D43: =IFERROR(Base!F40,"") -> Natalia | E43: =IFERROR(Base!G40,"-") -> 46115 | F43: =IFERROR(IF(Base!J40>0,Base!I40&" ("&Base!J40&"d atraso)",Base!I40),"") -> Concluído (d atraso)
B44: =IFERROR(LEFT(Base!#REF!,85),"") | C44: =IFERROR(LEFT(Base!#REF!,130),"") | D44: =IFERROR(Base!#REF!,"") | E44: =IFERROR(Base!#REF!,"-") -> - | F44: =IFERROR(IF(Base!#REF!>0,Base!#REF!&" ("&Base!#REF!&"d atraso)",Base!#REF!),"")
B45: =IFERROR(LEFT(Base!#REF!,85),"") | C45: =IFERROR(LEFT(Base!#REF!,130),"") | D45: =IFERROR(Base!#REF!,"") | E45: =IFERROR(Base!#REF!,"-") -> - | F45: =IFERROR(IF(Base!#REF!>0,Base!#REF!&" ("&Base!#REF!&"d atraso)",Base!#REF!),"")
B46: =IFERROR(LEFT(Base!D41,85),"") -> CANCELAMENTO NÃO REALIZADO (Conforme análise de verbatins dos clientes, existem muita | C46: =IFERROR(LEFT(Base!E41,130),"") -> Ampliar análise de casos de cancelamento não realizado para maior assertividade. | D46: =IFERROR(Base!F41,"") -> Diego | E46: =IFERROR(Base!G41,"-") -> 46133 | F46: =IFERROR(IF(Base!J41>0,Base!I41&" ("&Base!J41&"d atraso)",Base!I41),"") -> Em andamento (38d atraso)
B47: =IFERROR(LEFT(Base!D42,85),"") -> Token Anatel | C47: =IFERROR(LEFT(Base!E42,130),"") -> Selecionar e documentar casos de Token ANATEL (Ativação Simplificada) para abertura de chamado. | D47: =IFERROR(Base!F42,"") -> Cristiane | E47: =IFERROR(Base!G42,"-") -> 46133 | F47: =IFERROR(IF(Base!J42>0,Base!I42&" ("&Base!J42&"d atraso)",Base!I42),"") -> Concluído (d atraso)
B48: =IFERROR(LEFT(Base!D43,85),"") -> Lentidão SPN (Token e Bilhete) Atraso em relação aos bilhetes e token da ABR | C48: =IFERROR(LEFT(Base!E43,130),"") -> Continuar monitorando possíveis ocorrências de lentidão no SPN, especialmente em janelas de pico, com foco em bilhete, reagendamen | D48: =IFERROR(Base!F43,"") -> Galvão, Roldão, Diego e Cícera | E48: =IFERROR(Base!G43,"-") -> 46142 | F48: =IFERROR(IF(Base!J43>0,Base!I43&" ("&Base!J43&"d atraso)",Base!I43),"") -> Concluído (d atraso)
B49: =IFERROR(LEFT(Base!D44,85),"") -> Chamado ABR – SPN / Token Atraso em relação aos bilhetes e token da ABR | C49: =IFERROR(LEFT(Base!E44,130),"") -> Acompanhar o chamado junto à ABR e reforçar a cobrança para identificação da causa raiz, visando evitar novos impactos operacionai | D49: =IFERROR(Base!F44,"") -> Aline | E49: =IFERROR(Base!G44,"-") -> 46142 | F49: =IFERROR(IF(Base!J44>0,Base!I44&" ("&Base!J44&"d atraso)",Base!I44),"") -> Concluído (d atraso)
B50: =IFERROR(LEFT(Base!D45,85),"") -> Flex – Portabilidade Não Realizada Foi identificado que o sistema não estava enviando | C50: =IFERROR(LEFT(Base!E45,130),"") -> Avaliar se a falha no envio do código para logística, decorrente da migração do SAP, está impactando o aumento das reclamações de | D50: =IFERROR(Base!F45,"") -> Ieda | E50: =IFERROR(Base!G45,"-") -> 46142 | F50: =IFERROR(IF(Base!J45>0,Base!I45&" ("&Base!J45&"d atraso)",Base!I45),"") -> Concluído (d atraso)
B51: =IFERROR(LEFT(Base!D46,85),"") -> Foram discutidos casos de clientes em processo de portabilidade que não receberam o c | C51: =IFERROR(LEFT(Base!E46,130),"") -> Realizar reunião de alinhamento sobre casos MVNO sem chip e definição de devolução/estorno. | D51: =IFERROR(Base!F46,"") -> Tania | E51: =IFERROR(Base!G46,"-") -> 46148 | F51: =IFERROR(IF(Base!J46>0,Base!I46&" ("&Base!J46&"d atraso)",Base!I46),"") -> Atrasado (23d atraso)
B52: =IFERROR(LEFT(Base!D47,85),"") -> A ABR foi acionada no final de semana devido a instabilidades, durante uma manutenção | C52: =IFERROR(LEFT(Base!E47,130),"") -> Acionar TI para cobrança de prazo e tratamento da lentidão interna. | D52: =IFERROR(Base!F47,"") -> Aline | E52: =IFERROR(Base!G47,"-") -> 46148 | F52: =IFERROR(IF(Base!J47>0,Base!I47&" ("&Base!J47&"d atraso)",Base!I47),"") -> Concluído (d atraso)
B53: =IFERROR(LEFT(Base!D48,85),"") -> Foi discutido sobre os planos de ações em andamento relacionados ao cliente em loja p | C53: =IFERROR(LEFT(Base!E48,130),"") -> Definir e comunicar data do workshop em lojas. | D53: =IFERROR(Base!F48,"") -> Borges | E53: =IFERROR(Base!G48,"-") -> 46148 | F53: =IFERROR(IF(Base!J48>0,Base!I48&" ("&Base!J48&"d atraso)",Base!I48),"") -> Atrasado (23d atraso)
B54: =IFERROR(LEFT(Base!#REF!,85),"") | C54: =IFERROR(LEFT(Base!#REF!,130),"") | D54: =IFERROR(Base!#REF!,"") | E54: =IFERROR(Base!#REF!,"-") -> - | F54: =IFERROR(IF(Base!#REF!>0,Base!#REF!&" ("&Base!#REF!&"d atraso)",Base!#REF!),"")
